Workbook
Name ExternalData_1: FactSales!#REF!
Name Slicer_Channel: #N/A
Name Slicer_Regions: #N/A
Name Slicer_Segment: #N/A

Sheet Dashboard
B2: Q1 2024 Retail Performance
B3: Source: FactSales ~refreshed automatically
B5: Total Revenue: | D5: Order Count: | F5: Total Quantity sold: | H5: Average Order Value: | J5: Active Customers:
B6: =GETPIVOTDATA("LineRevenue",Pivots!$A$1,"Quarter",1) -> 2032740.2 | D6: =GETPIVOTDATA("Quantity",Pivots!$O$1,"Quarter",1) -> 280 | F6: =GETPIVOTDATA("Quantity",Pivots!$H$1,"Quarter",1) -> 2003 | H6: =B6/D6 -> 7259.7864 | J6: {=COUNTA(_xlfn.UNIQUE(_xlfn._xlws.FILTER(FactSales!F2:F100000,(FactSales!D2:D100000=1)*(FactSales!F2:F100000<>""))))} -> 77
C24: Revenue: | D24: Quantity: | E24: Revenue as % of total:
B25: 4K Monitor | C25: =IFERROR(GETPIVOTDATA("Sum of LineRevenue",Pivots!$H$9,"Quarter",1,"Product","4K Monitor"),0) -> 217733.05 | D25: =IFERROR(GETPIVOTDATA("Sum of Quantity",Pivots!$H$9,"Quarter",1,"Product","4K Monitor"),0) -> 182 | E25: =C25/SUM(C$25:C$34) -> 0.1436783
B26: USB-C Hub | C26: =IFERROR(GETPIVOTDATA("Sum of LineRevenue",Pivots!$H$9,"Quarter",1,"Product","USB-C Hub"),0) -> 174342.17 | D26: =IFERROR(GETPIVOTDATA("Sum of Quantity",Pivots!$H$9,"Quarter",1,"Product","USB-C Hub"),0) -> 152 | E26: =C26/SUM(C$25:C$34) -> 0.11504541
B27: Standing Desk | C27: =IFERROR(GETPIVOTDATA("Sum of LineRevenue",Pivots!$H$9,"Quarter",1,"Product","Standing Desk"),0) -> 153580.97 | D27: =IFERROR(GETPIVOTDATA("Sum of Quantity",Pivots!$H$9,"Quarter",1,"Product","Standing Desk"),0) -> 136 | E27: =C27/SUM(C$25:C$34) -> 0.10134545
B28: Wireless Mouse | C28: =IFERROR(GETPIVOTDATA("Sum of LineRevenue",Pivots!$H$9,"Quarter",1,"Product","Wireless Mouse"),0) -> 149454.24 | D28: =IFERROR(GETPIVOTDATA("Sum of Quantity",Pivots!$H$9,"Quarter",1,"Product","Wireless Mouse"),0) -> 139 | E28: =C28/SUM(C$25:C$34) -> 0.098622287
B29: Tablet | C29: =IFERROR(GETPIVOTDATA("Sum of LineRevenue",Pivots!$H$9,"Quarter",1,"Product","Tablet"),0) -> 146178.71 | D29: =IFERROR(GETPIVOTDATA("Sum of Quantity",Pivots!$H$9,"Quarter",1,"Product","Tablet"),0) -> 138 | E29: =C29/SUM(C$25:C$34) -> 0.096460821
B30: Docking Station | C30: =IFERROR(GETPIVOTDATA("Sum of LineRevenue",Pivots!$H$9,"Quarter",1,"Product","Docking Station"),0) -> 144493.44 | D30: =IFERROR(GETPIVOTDATA("Sum of Quantity",Pivots!$H$9,"Quarter",1,"Product","Docking Station"),0) -> 122 | E30: =C30/SUM(C$25:C$34) -> 0.095348741
B31: Power Bank | C31: =IFERROR(GETPIVOTDATA("Sum of LineRevenue",Pivots!$H$9,"Quarter",1,"Product","Power Bank"),0) -> 137103.39 | D31: =IFERROR(GETPIVOTDATA("Sum of Quantity",Pivots!$H$9,"Quarter",1,"Product","Power Bank"),0) -> 171 | E31: =C31/SUM(C$25:C$34) -> 0.090472173
B32: Mechanical Keyboard | C32: =IFERROR(GETPIVOTDATA("Sum of LineRevenue",Pivots!$H$9,"Quarter",1,"Product","Mechanical Keyboard"),0) -> 136095.42 | D32: =IFERROR(GETPIVOTDATA("Sum of Quantity",Pivots!$H$9,"Quarter",1,"Product","Mechanical Keyboard"),0) -> 144 | E32: =C32/SUM(C$25:C$34) -> 0.089807031
B33: Laptop Pro | C33: =IFERROR(GETPIVOTDATA("Sum of LineRevenue",Pivots!$H$9,"Quarter",1,"Product","Laptop Pro"),0) -> 132025.2 | D33: =IFERROR(GETPIVOTDATA("Sum of Quantity",Pivots!$H$9,"Quarter",1,"Product","Laptop Pro"),0) -> 134 | E33: =C33/SUM(C$25:C$34) -> 0.087121163
B34: Cable Kit | C34: =IFERROR(GETPIVOTDATA("Sum of LineRevenue",Pivots!$H$9,"Quarter",1,"Product","Cable Kit"),0) -> 124413.95 | D34: =IFERROR(GETPIVOTDATA("Sum of Quantity",Pivots!$H$9,"Quarter",1,"Product","Cable Kit"),0) -> 142 | E34: =C34/SUM(C$25:C$34) -> 0.08209863
B38: Q2 2024 Retail Performance
B39: Source: FactSales ~refreshed automatically
B41: Total Revenue: | D41: Order Count: | F41: Total Quantity sold: | H41: Average Order Value: | J41: Active Customers:
B42: =GETPIVOTDATA("LineRevenue",Pivots!$A$1,"Quarter",2) -> 2286079.8 | D42: =GETPIVOTDATA("Quantity",Pivots!$O$1,"Quarter",2) -> 302 | F42: =GETPIVOTDATA("Quantity",Pivots!$H$1,"Quarter",2) -> 2261 | H42: =B42/D42 -> 7569.8008 | J42: {=COUNTA(_xlfn.UNIQUE(_xlfn._xlws.FILTER(FactSales!F:F,(FactSales!D:D=2)*(FactSales!F:F<>""))))} -> 80
B43: QoQ:
B44: =(B42-B6)/B6 -> 0.12462963 | D44: =(D42-D6)/D6 -> 0.078571429 | F44: =(F42-F6)/F6 -> 0.12880679 | H44: =(H42-H6)/H6 -> 0.04270297 | J44: =(J42-J6)/J6 -> 0.038961039
C62: Revenue: | D62: Quantity: | E62: Revenue as % of total:
B63: Office Chair | C63: =IFERROR(GETPIVOTDATA("Sum of LineRevenue",Pivots!$N$9,"Quarter",2,"Product","Office Chair"),0) -> 244372.5 | D63: =IFERROR(GETPIVOTDATA("Sum of Quantity",Pivots!$N$9,"Quarter",2,"Product","Office Chair"),0) -> 214 | E63: =C63/SUM(C$25:C$34) -> 0.16125722
B64: Standing Desk | C64: =IFERROR(GETPIVOTDATA("Sum of LineRevenue",Pivots!$N$9,"Quarter",2,"Product","Standing Desk"),0) -> 198469.73 | D64: =IFERROR(GETPIVOTDATA("Sum of Quantity",Pivots!$N$9,"Quarter",2,"Product","Standing Desk"),0) -> 191 | E64: =C64/SUM(C$25:C$34) -> 0.13096677
B65: Webcam HD | C65: =IFERROR(GETPIVOTDATA("Sum of LineRevenue",Pivots!$N$9,"Quarter",2,"Product","Webcam HD"),0) -> 175600.53 | D65: =IFERROR(GETPIVOTDATA("Sum of Quantity",Pivots!$N$9,"Quarter",2,"Product","Webcam HD"),0) -> 150 | E65: =C65/SUM(C$25:C$34) -> 0.11587578
B66: Cable Kit | C66: =IFERROR(GETPIVOTDATA("Sum of LineRevenue",Pivots!$N$9,"Quarter",2,"Product","Cable Kit"),0) -> 172864.75 | D66: =IFERROR(GETPIVOTDATA("Sum of Quantity",Pivots!$N$9,"Quarter",2,"Product","Cable Kit"),0) -> 184 | E66: =C66/SUM(C$25:C$34) -> 0.11407048
B67: Power Bank | C67: =IFERROR(GETPIVOTDATA("Sum of LineRevenue",Pivots!$N$9,"Quarter",2,"Product","Power Bank"),0) -> 171465.9 | D67: =IFERROR(GETPIVOTDATA("Sum of Quantity",Pivots!$N$9,"Quarter",2,"Product","Power Bank"),0) -> 161 | E67: =C67/SUM(C$25:C$34) -> 0.1131474
B68: Headset | C68: =IFERROR(GETPIVOTDATA("Sum of LineRevenue",Pivots!$N$9,"Quarter",2,"Product","Headset"),0) -> 167087.39 | D68: =IFERROR(GETPIVOTDATA("Sum of Quantity",Pivots!$N$9,"Quarter",2,"Product","Headset"),0) -> 198 | E68: =C68/SUM(C$25:C$34) -> 0.1102581
B69: Tablet | C69: =IFERROR(GETPIVOTDATA("Sum of LineRevenue",Pivots!$N$9,"Quarter",2,"Product","Tablet"),0) -> 160318.71 | D69: =IFERROR(GETPIVOTDATA("Sum of Quantity",Pivots!$N$9,"Quarter",2,"Product","Tablet"),0) -> 147 | E69: =C69/SUM(C$25:C$34) -> 0.10579156
B70: Desk Lamp | C70: =IFERROR(GETPIVOTDATA("Sum of LineRevenue",Pivots!$N$9,"Quarter",2,"Product","Desk Lamp"),0) -> 145372.48 | D70: =IFERROR(GETPIVOTDATA("Sum of Quantity",Pivots!$N$9,"Quarter",2,"Product","Desk Lamp"),0) -> 120 | E70: =C70/SUM(C$25:C$34) -> 0.095928804
B71: Wireless Mouse | C71: =IFERROR(GETPIVOTDATA("Sum of LineRevenue",Pivots!$N$9,"Quarter",2,"Product","Wireless Mouse"),0) -> 144578.51 | D71: =IFERROR(GETPIVOTDATA("Sum of Quantity",Pivots!$N$9,"Quarter",2,"Product","Wireless Mouse"),0) -> 152 | E71: =C71/SUM(C$25:C$34) -> 0.095404877
B72: Laptop Pro | C72: =IFERROR(GETPIVOTDATA("Sum of LineRevenue",Pivots!$N$9,"Quarter",2,"Product","Laptop Pro"),0) -> 129192.01 | D72: =IFERROR(GETPIVOTDATA("Sum of Quantity",Pivots!$N$9,"Quarter",2,"Product","Laptop Pro"),0) -> 130 | E72: =C72/SUM(C$25:C$34) -> 0.08525159

Sheet Lookups
A1: CustomerID | B1: Revenue | C1: CustomerName | D1: Tier | G1: Threshold | H1: Tiername
A2: 6 | B2: =SUMIF(FactSales!F:F,Lookups!A2,FactSales!N:N) -> 106272.6 | C2: =_xlfn.XLOOKUP(A2,FactSales!F:F,FactSales!G:G,"Unkown",0,1) -> Sophie Johnson | D2: =_xlfn.XLOOKUP(B2,Ranks[Threshold],Ranks[Tiername]," ",-1,1) -> Platinum | G2: 0 | H2: Bronze
A3: 10 | B3: =SUMIF(FactSales!F:F,Lookups!A3,FactSales!N:N) -> 96558.25 | C3: =_xlfn.XLOOKUP(A3,FactSales!F:F,FactSales!G:G,"Unkown",0,1) -> Sophie Brown | D3: =_xlfn.XLOOKUP(B3,Ranks[Threshold],Ranks[Tiername]," ",-1,1) -> Gold | G3: 50000 | H3: Silver
A4: 15 | B4: =SUMIF(FactSales!F:F,Lookups!A4,FactSales!N:N) -> 71059.2 | C4: =_xlfn.XLOOKUP(A4,FactSales!F:F,FactSales!G:G,"Unkown",0,1) -> James Brown | D4: =_xlfn.XLOOKUP(B4,Ranks[Threshold],Ranks[Tiername]," ",-1,1) -> Silver | G4: 75000 | H4: Gold
A5: 21 | B5: =SUMIF(FactSales!F:F,Lookups!A5,FactSales!N:N) -> 156932.35 | C5: =_xlfn.XLOOKUP(A5,FactSales!F:F,FactSales!G:G,"Unkown",0,1) -> Anna Johnson | D5: =_xlfn.XLOOKUP(B5,Ranks[Threshold],Ranks[Tiername]," ",-1,1) -> Platinum | G5: 100000 | H5: Platinum
A6: 30 | B6: =SUMIF(FactSales!F:F,Lookups!A6,FactSales!N:N) -> 98836.95 | C6: =_xlfn.XLOOKUP(A6,FactSales!F:F,FactSales!G:G,"Unkown",0,1) -> Anna Dupont | D6: =_xlfn.XLOOKUP(B6,Ranks[Threshold],Ranks[Tiername]," ",-1,1) -> Gold
A7: 76 | B7: =SUMIF(FactSales!F:F,Lookups!A7,FactSales!N:N) -> 102188.26 | C7: =_xlfn.XLOOKUP(A7,FactSales!F:F,FactSales!G:G,"Unkown",0,1) -> Lisa Martin | D7: =_xlfn.XLOOKUP(B7,Ranks[Threshold],Ranks[Tiername]," ",-1,1) -> Platinum
A8: 51 | B8: =SUMIF(FactSales!F:F,Lookups!A8,FactSales!N:N) -> 134156.84 | C8: =_xlfn.XLOOKUP(A8,FactSales!F:F,FactSales!G:G,"Unkown",0,1) -> Maria Muller | D8: =_xlfn.XLOOKUP(B8,Ranks[Threshold],Ranks[Tiername]," ",-1,1) -> Platinum
A9: 77 | B9: =SUMIF(FactSales!F:F,Lookups!A9,FactSales!N:N) -> 109325.21 | C9: =_xlfn.XLOOKUP(A9,FactSales!F:F,FactSales!G:G,"Unkown",0,1) -> Pierre Brown | D9: =_xlfn.XLOOKUP(B9,Ranks[Threshold],Ranks[Tiername]," ",-1,1) -> Platinum
A10: 19 | B10: =SUMIF(FactSales!F:F,Lookups!A10,FactSales!N:N) -> 78113.15 | C10: =_xlfn.XLOOKUP(A10,FactSales!F:F,FactSales!G:G,"Unkown",0,1) -> Lucas Chen | D10: =_xlfn.XLOOKUP(B10,Ranks[Threshold],Ranks[Tiername]," ",-1,1) -> Gold
A11: 21 | B11: =SUMIF(FactSales!F:F,Lookups!A11,FactSales!N:N) -> 156932.35 | C11: =_xlfn.XLOOKUP(A11,FactSales!F:F,FactSales!G:G,"Unkown",0,1) -> Anna Johnson | D11: =_xlfn.XLOOKUP(B11,Ranks[Threshold],Ranks[Tiername]," ",-1,1) -> Platinum
A12: 35 | B12: =SUMIF(FactSales!F:F,Lookups!A12,FactSales!N:N) -> 116290.7 | C12: =_xlfn.XLOOKUP(A12,FactSales!F:F,FactSales!G:G,"Unkown",0,1) -> Pierre Smith | D12: =_xlfn.XLOOKUP(B12,Ranks[Threshold],Ranks[Tiername]," ",-1,1) -> Platinum
A13: 33 | B13: =SUMIF(FactSales!F:F,Lookups!A13,FactSales!N:N) -> 94083.49 | C13: =_xlfn.XLOOKUP(A13,FactSales!F:F,FactSales!G:G,"Unkown",0,1) -> Emma Smith | D13: =_xlfn.XLOOKUP(B13,Ranks[Threshold],Ranks[Tiername]," ",-1,1) -> Gold
A14: 65 | B14: =SUMIF(FactSales!F:F,Lookups!A14,FactSales!N:N) -> 147439.86 | C14: =_xlfn.XLOOKUP(A14,FactSales!F:F,FactSales!G:G,"Unkown",0,1) -> Marie Chen | D14: =_xlfn.XLOOKUP(B14,Ranks[Threshold],Ranks[Tiername]," ",-1,1) -> Platinum
A15: 55 | B15: =SUMIF(FactSales!F:F,Lookups!A15,FactSales!N:N) -> 155556.76 | C15: =_xlfn.XLOOKUP(A15,FactSales!F:F,FactSales!G:G,"Unkown",0,1) -> Sophie Martin | D15: =_xlfn.XLOOKUP(B15,Ranks[Threshold],Ranks[Tiername]," ",-1,1) -> Platinum
A16: 36 | B16: =SUMIF(FactSales!F:F,Lookups!A16,FactSales!N:N) -> 84311 | C16: =_xlfn.XLOOKUP(A16,FactSales!F:F,FactSales!G:G,"Unkown",0,1) -> Maria Wilson | D16: =_xlfn.XLOOKUP(B16,Ranks[Threshold],Ranks[Tiername]," ",-1,1) -> Gold
A17: 27 | B17: =SUMIF(FactSales!F:F,Lookups!A17,FactSales!N:N) -> 181554.9 | C17: =_xlfn.XLOOKUP(A17,FactSales!F:F,FactSales!G:G,"Unkown",0,1) -> Nora Muller | D17: =_xlfn.XLOOKUP(B17,Ranks[Threshold],Ranks[Tiername]," ",-1,1) -> Platinum
... A22: 52 | B22: =SUMIF(FactSales!F:F,Lookups!A22,FactSales!N:N) -> 101644.86 | C22: =_xlfn.XLOOKUP(A22,FactSales!F:F,FactSales!G:G,"Unkown",0,1) -> James Garcia | D22: =_xlfn.XLOOKUP(B22,Ranks[Threshold],Ranks[Tiername]," ",-1,1) -> Platinum

Sheet Pivots
A1: Sum of LineRevenue | B1: Quarter | H1: Sum of Quantity | I1: Column Labels | O1: Count of Quantity | P1: Column Labels
A2: Region | B2: 1 | C2: 2 | D2: 3 | E2: 4 | F2: Grand Total | H2: Row Labels | I2: 1 | J2: 2 | K2: 3 | L2: 4 | M2: Grand Total | O2: Row Labels | P2: 1 | Q2: 2 | R2: 3 | S2: 4 | T2: Grand Total
A3: APAC | B3: 395941.75 | C3: 509930.43 | D3: 386369.01 | E3: 387848.86 | F3: 1680090.1 | H3: APAC | I3: 341 | J3: 471 | K3: 358 | L3: 343 | M3: 1513 | O3: APAC | P3: 51 | Q3: 60 | R3: 50 | S3: 54 | T3: 215
A4: Europe | B4: 957170.24 | C4: 1030634.6 | D4: 1155091.6 | E4: 1182563 | F4: 4325459.4 | H4: Europe | I4: 922 | J4: 1047 | K4: 1112 | L4: 1071 | M4: 4152 | O4: Europe | P4: 134 | Q4: 139 | R4: 149 | S4: 146 | T4: 568
A5: LATAM | B5: 393139.26 | C5: 282127.31 | D5: 301598.24 | E5: 471165.9 | F5: 1448030.7 | H5: LATAM | I5: 408 | J5: 294 | K5: 331 | L5: 414 | M5: 1447 | O5: LATAM | P5: 53 | Q5: 41 | R5: 47 | S5: 48 | T5: 189
A6: North America | B6: 286488.93 | C6: 463387.49 | D6: 311804.13 | E6: 388880.08 | F6: 1450560.6 | H6: North America | I6: 332 | J6: 449 | K6: 337 | L6: 345 | M6: 1463 | O6: North America | P6: 42 | Q6: 62 | R6: 45 | S6: 45 | T6: 194
A7: Grand Total | B7: 2032740.2 | C7: 2286079.8 | D7: 2154863 | E7: 2430457.8 | F7: 8904140.8 | H7: Grand Total | I7: 2003 | J7: 2261 | K7: 2138 | L7: 2173 | M7: 8575 | O7: Grand Total | P7: 280 | Q7: 302 | R7: 291 | S7: 293 | T7: 1166
A9: Row Labels | B9: Sum of LineRevenue | C9: Sum of Quantity | I9: Column Labels | O9: Column Labels
A10: Cable Kit | B10: 753082.78 | C10: 703 | I10: 1 | K10: Total Sum of LineRevenue | L10: Total Sum of Quantity | O10: 2 | Q10: Total Sum of LineRevenue | R10: Total Sum of Quantity
A11: Tablet | B11: 751019.11 | C11: 672 | H11: Row Labels | I11: Sum of LineRevenue | J11: Sum of Quantity | N11: Row Labels | O11: Sum of LineRevenue | P11: Sum of Quantity
A12: 4K Monitor | B12: 655768.56 | C12: 601 | H12: 4K Monitor | I12: 217733.05 | J12: 182 | K12: 217733.05 | L12: 182 | N12: Office Chair | O12: 244372.5 | P12: 214 | Q12: 244372.5 | R12: 214
A13: Headset | B13: 630461.48 | C13: 640 | H13: USB-C Hub | I13: 174342.17 | J13: 152 | K13: 174342.17 | L13: 152 | N13: Standing Desk | O13: 198469.73 | P13: 191 | Q13: 198469.73 | R13: 191
A14: Standing Desk | B14: 618651.55 | C14: 553 | H14: Standing Desk | I14: 153580.97 | J14: 136 | K14: 153580.97 | L14: 136 | N14: Webcam HD | O14: 175600.53 | P14: 150 | Q14: 175600.53 | R14: 150
A15: USB-C Hub | B15: 615909.75 | C15: 565 | H15: Wireless Mouse | I15: 149454.24 | J15: 139 | K15: 149454.24 | L15: 139 | N15: Cable Kit | O15: 172864.75 | P15: 184 | Q15: 172864.75 | R15: 184
A16: Power Bank | B16: 606858.79 | C16: 594 | H16: Tablet | I16: 146178.71 | J16: 138 | K16: 146178.71 | L16: 138 | N16: Power Bank | O16: 171465.9 | P16: 161 | Q16: 171465.9 | R16: 161
A17: Office Chair | B17: 595665.68 | C17: 602 | H17: Docking Station | I17: 144493.44 | J17: 122 | K17: 144493.44 | L17: 122 | N17: Headset | O17: 167087.39 | P17: 198 | Q17: 167087.39 | R17: 198
A18: Laptop Pro | B18: 590325.76 | C18: 578 | H18: Power Bank | I18: 137103.39 | J18: 171 | K18: 137103.39 | L18: 171 | N18: Tablet | O18: 160318.71 | P18: 147 | Q18: 160318.71 | R18: 147
A19: Mechanical Keyboard | B19: 570986 | C19: 552 | H19: Mechanical Keyboard | I19: 136095.42 | J19: 144 | K19: 136095.42 | L19: 144 | N19: Desk Lamp | O19: 145372.48 | P19: 120 | Q19: 145372.48 | R19: 120
A20: Grand Total | B20: 6388729.5 | C20: 6060 | H20: Laptop Pro | I20: 132025.2 | J20: 134 | K20: 132025.2 | L20: 134 | N20: Wireless Mouse | O20: 144578.51 | P20: 152 | Q20: 144578.51 | R20: 152
H21: Cable Kit | I21: 124413.95 | J21: 142 | K21: 124413.95 | L21: 142 | N21: Laptop Pro | O21: 129192.01 | P21: 130 | Q21: 129192.01 | R21: 130
A22: Sum of LineRevenue | B22: Column Labels | H22: Grand Total | I22: 1515420.5 | J22: 1460 | K22: 1515420.5 | L22: 1460 | N22: Grand Total | O22: 1709322.5 | P22: 1647 | Q22: 1709322.5 | R22: 1647
A23: Row Labels | B23: mobile | C23: phone | D23: store | E23: web | F23: Grand Total
A24: Consumer | B24: 0.30952103 | C24: 0.25208042 | D24: 0.25636192 | E24: 0.25690165 | F24: 0.2720858
A25: Enterprise | B25: 0.15771537 | C25: 0.23620962 | D25: 0.15091176 | E25: 0.18984141 | F25: 0.18192159
A26: Mid-Market | B26: 0.30375301 | C26: 0.30708217 | D26: 0.31636498 | E26: 0.30629847 | F26: 0.30711984
A27: SMB | B27: 0.22901059 | C27: 0.20462779 | D27: 0.27636134 | E27: 0.24695847 | F27: 0.23887277
A28: Grand Total | B28: 1 | C28: 1 | D28: 1 | E28: 1 | F28: 1
A30: Row Labels | B30: Sum of LineRevenue
A31: jan | B31: 720956.39
A32: feb | B32: 653542.4
A33: mrt | B33: 658241.39
A34: apr | B34: 770811.09
A35: mei | B35: 724605.47
A36: jun | B36: 790663.28
A37: jul | B37: 729540.02
A38: aug | B38: 798333.34
A39: sep | B39: 626989.61
A40: okt | B40: 816977.53
A41: nov | B41: 808580.9
A42: dec | B42: 804899.41
...

Sheet FactSales
A1: OrderID | B1: OrderDate | C1: Year | D1: Quarter | E1: MonthNum | F1: CustomerID | G1: Name | H1: Segment | I1: Country | J1: Regions | K1: Product | L1: Quantity | M1: UnitPrice | N1: LineRevenue | O1: OrderSize | P1: Channel | Q1: Status
A2: 202400705 | B2: 45626 | C2: 2024 | D2: 4 | E2: 11 | F2: 10 | G2: Sophie Brown | H2: Mid-Market | I2: France | J2: Europe | K2: Tablet | L2: 12 | M2: 1157.47 | N2: 13889.64 | O2: Bulk | P2: store | Q2: completed
A3: 202400909 | B3: 45583 | C3: 2024 | D3: 4 | E3: 10 | F3: 7 | G3: Carlos Muller | H3: Consumer | I3: Netherlands | J3: Europe | K3: Desk Lamp | L3: 8 | M3: 992.42 | N3: 7939.36 | O3: Medium | P3: mobile | Q3: completed
A4: 202401159 | B4: 45443 | C4: 2024 | D4: 2 | E4: 5 | F4: 7 | G4: Carlos Muller | H4: Consumer | I4: Netherlands | J4: Europe | K4: Tablet | L4: 6 | M4: 1912.72 | N4: 11476.32 | O4: Medium | P4: mobile | Q4: cancelled
A5: 202400763 | B5: 45310 | C5: 2024 | D5: 1 | E5: 1 | F5: 2 | G5: John Wilson | H5: Mid-market | I5: Mexico | J5: LATAM | K5: Cable Kit | L5: 2 | M5: 1482.51 | N5: 2965.02 | O5: Single | P5: mobile | Q5: completed
A6: 202400211 | B6: 45508 | C6: 2024 | D6: 3 | E6: 8 | F6: 50 | G6: Carlos Tanaka | H6: Enterprise | I6: Italy | J6: Europe | K6: Standing Desk | L6: 11 | M6: 1252.65 | N6: 13779.15 | O6: Bulk | P6: mobile | Q6: shipped
A7: 202400045 | B7: 45576 | C7: 2024 | D7: 4 | E7: 10 | F7: 50 | G7: Carlos Tanaka | H7: Enterprise | I7: Italy | J7: Europe | K7: Desk Lamp | L7: 1 | M7: 343.63 | N7: 343.63 | O7: Single | P7: store | Q7: pending
A8: 202400077 | B8: 45562 | C8: 2024 | D8: 3 | E8: 9 | F8: 50 | G8: Carlos Tanaka | H8: Enterprise | I8: Italy | J8: Europe | K8: Desk Lamp | L8: 14 | M8: 1369.54 | N8: 19173.56 | O8: Bulk | P8: store | Q8: shipped
A9: 202400024 | B9: 45656 | C9: 2024 | D9: 4 | E9: 12 | F9: 50 | G9: Carlos Tanaka | H9: Enterprise | I9: Italy | J9: Europe | K9: Mechanical Keyboard | L9: 4 | M9: 1829.01 | N9: 7316.04 | O9: Medium | P9: web | Q9: completed
A10: 202400600 | B10: 45382 | C10: 2024 | D10: 1 | E10: 3 | F10: 3 | G10: Maria Smith | H10: Consumer | I10: Italy | J10: Europe | K10: Desk Lamp | L10: 2 | M10: 48.2 | N10: 96.4 | O10: Single | P10: mobile | Q10: completed
A11: 202400714 | B11: 45321 | C11: 2024 | D11: 1 | E11: 1 | F11: 3 | G11: Maria Smith | H11: Consumer | I11: Italy | J11: Europe | K11: Tablet | L11: 5 | M11: 670.18 | N11: 3350.9 | O11: Medium | P11: mobile | Q11: completed
A12: 202400383 | B12: 45604 | C12: 2024 | D12: 4 | E12: 11 | F12: 3 | G12: Maria Smith | H12: Consumer | I12: Italy | J12: Europe | K12: Mechanical Keyboard | L12: 9 | M12: 1627.41 | N12: 14646.69 | O12: Medium | P12: web | Q12: refunded
A13: 202401010 | B13: 45340 | C13: 2024 | D13: 1 | E13: 2 | F13: 3 | G13: Maria Smith | H13: Consumer | I13: Italy | J13: Europe | K13: Mechanical Keyboard | L13: 14 | M13: 1124.03 | N13: 15736.42 | O13: Bulk | P13: mobile | Q13: completed
... A1167: 202401127 | B1167: 45656 | C1167: 2024 | D1167: 4 | E1167: 12 | F1167: 42 | G1167: James Nilsson | H1167: Consumer | I1167: Italy | J1167: Europe | K1167: Webcam HD | L1167: 9 | M1167: 778.73 | N1167: 7008.57 | O1167: Medium | P1167: web | Q1167: refunded
